Workbook

Sheet Project Info
B2: PROJECT INFORMATION
B4: Edit values in column C. The Cover and Appendix Cover tabs display them.
B6: Project Name | C6: Qiddiya D-18 - TSE Irrigation Storage Tanks (RFP-027)
B7: Client | C7: Qiddiya Investment Company
B8: Address | C8: Qiddiya, Riyadh, Kingdom of Saudi Arabia
B9: Contract Reference | C9: QPMO-410-CT-05958
B10: Contractor | C10: SAMA Construction
B11: Engineer | C11: KEO International Consultants
B12: Cost Consultant | C12: WT Partnership
B13: Document Title | C13: Cost Assessment of the Contractor's Proposal - TSE Irrigation Storage Tanks (RFP-027) - Rev 02
B14: Document Date | C14: 30-Sep-2026
B15: Document Reference | C15: RFP-027 / SAMACO-RRFP-000001
B16: Appendix Letter | C16: A
B17: Appendix Description | C17: Cost Assessment of the Contractor's Proposal - TSE Irrigation Storage Tanks (RFP-027)
B18: Cover Subtitle (auto) | C18: =C13 & " | " & C14 -> Cost Assessment of the Contractor's Proposal - TSE Irrigation Storage Tanks (RFP-027) - Rev 02 | 30-Sep-2026
B19: Cover Reference (auto) | C19: ="Reference: " & C15 -> Reference: RFP-027 / SAMACO-RRFP-000001
B20: Appendix Title (auto) | C20: ="Appendix " & C16 -> Appendix A

Sheet Cover

Sheet Appendix Cover

Sheet Assessment
A1: COST ASSESSMENT OF THE CONTRACTOR'S PROPOSAL
A2: TSE Irrigation Storage Tanks and Associated Pipeworks (RFP-027) - Contract QPMO-410-CT-05958
A3: Contractor: SAMA Construction | Engineer: KEO | Cost Consultant: WT Partnership | Rev 02, 30-Sep-2026
A4: ="Purpose: to value the Contractor's revised proposal ref. SAMACO-RRFP-000001 dated 13-Aug-2026 for the 2 No. TSE irrigation storage tanks, dismantling of damaged Tank-1, associated pipework and testing. Result: the proposal of SAR " & TEXT(F21,"#,##0.00") & " is assessed at SAR " & TEXT(K21,"#,##0.00") & ", both excluding VAT (row 21). Basis: supplier quotations where the Contractor obtained them (Items 3 and 6), first-principles build-ups elsewhere ('Build-Up' tab), with every time-related period taken from the Contractor's programme of 29-"&"Sep-2026 ('Programme' tab) - a programme under the Engineer's approval, not an agreed basis. Status: preliminary - items marked Provisional depend on confirmations still outstanding. Rev 02 replaces Rev 01 dated 17-Sep-2026 (SAR " & TEXT(6921685.64,"#,##0.00") & ")." -> Purpose: to value the Contractor's revised proposal ref. SAMACO-RRFP-000001 dated 13-Aug-2026 for the 2 No. TSE irrigation storage tanks, dismantling of damaged Tank-1, associated pipework and testing. Result: the proposal of SAR 8,110,296.62 is assessed at SAR 6,984,428.39, both excluding VAT (row 21). Basis: supplier quotations where the Contractor obtained them (Items 3 and 6), first-principles build-ups elsewhere ('Build-Up' tab), with every time-related period taken from the Contractor's programme of 29-Sep-2026 ('Programme' tab) - a programme under the Engineer's approval, not an agreed basis. Status: preliminary - items marked Provisional depend on confirmations still outstanding. Rev 02 replaces Rev 01 dated 17-Sep-2026 (SAR 6,921,685.64).
C5: CONTRACTOR'S PROPOSAL - SAMACO-RRFP-000001, 13-AUG-2026, AS SUBMITTED | H5: ASSESSMENT | O5: VARIANCE
A6: Item | B6: Description | C6: Unit | D6: Qty | E6: Rate (SAR) | F6: Amount (SAR) | G6: Substantiation submitted | H6: Unit | I6: Qty | J6: Rate (SAR) | K6: Amount (SAR) | L6: Assessment | M6: Basis of rate | N6: Status | O6: Variance (SAR) | P6: Variance %
A7: GENERAL ITEMS
A8: 1 | B8: Site Mobilization and Demobilization; Site Temporary Facilities, Welfare, Personnel, and Resources (Stand Alone) | C8: LS | D8: 1 | E8: 680000 | F8: 680000 | G8: Percentage allocation of the lump sum; no quantities or rates. See 'Build-Up Comparison' | H8: LS | I8: 1 | J8: ='Build-Up'!$F$32 -> 319680.56 | K8: =I8*J8 -> 319680.56 | L8: Separate site establishment: the tank site is in the lower plateau, outside the D-18 boundary, so site staff, welfare, water, security, insurance endorsement, mobilisation, demobilisation and close-out are assessed for the site period derived from the Contractor's programme of 29-Sep-2026 ('Programme' tab, D1): mobilisation on 22-Aug-2026 to the end of demobilisation, the end being set by the external readiness milestone of 03-Dec-2026 and the tie-in, sequential testing, commissioning and demobilisation that follow; site staff are assessed role by role by phase ('Programme' tab, Section 4). Design resources are shared with the main Contract. See 'Build-Up' Item 1, 'Programme' Sections 3 to 5 and 'Build-Up Comparison' Section 3. | M8: Star Rate | N8: Assessed | O8: =F8-K8 -> 360319.44 | P8: =IF(K8=0,"",(F8-K8)/K8) -> 1.1271234
A9: DESIGN AND ENGINEERING
A10: 2 | B10: Design and Engineering works | C10: LS | D10: 1 | E10: 85000 | F10: 85000 | G10: None | H10: LS | I10: 1 | J10: ='Build-Up'!$F$41 -> 55000 | K10: =I10*J10 -> 55000 | L10: Assessed build-up; tank design sits with the supplier. See 'Build-Up' Item 2. | M10: Star Rate | N10: Assessed | O10: =F10-K10 -> 30000 | P10: =IF(K10=0,"",(F10-K10)/K10) -> 0.54545455
A11: SITE WORKS
A12: 3 | B12: Safe Dismantling & Removal from Site of Damaged TSE Tank - 1 | C12: Ls | D12: 1 | E12: 71000 | F12: 71000 | G12: Supplier quotation Al Mousa S04647 dated 10-Aug-2026 | H12: Ls | I12: 1 | J12: ='Build-Up'!$F$47 -> 71000 | K12: =I12*J12 -> 71000 | L12: Lowest of the Contractor's three quotations, adopted for dismantling, segregation and loading only on the scope recorded in the previous revision; the quotation itself is not attached to this revision and its scope split is not yet confirmed in writing. Haulage and handover are Item 4. See 'Build-Up' Item 3. | M12: Market Tested | N12: Provisional - scope confirmation | O12: =F12-K12 -> 0 | P12: =IF(K12=0,"",(F12-K12)/K12) -> 0
A13: 4 | B13: Removal and Disposal of Damaged TSE Tank to Approved Landfill | C13: LS | D13: 1 | E13: 10500 | F13: 10500 | G13: None | H13: LS | I13: 1 | J13: ='Build-Up'!$F$69 -> 6300 | K13: =I13*J13 -> 6300 | L13: Haulage only. The Engineer's (KEO) email of 30-Aug-2026: materials are handed to the Employer locally, so no disposal or tipping applies. Location and rate to be confirmed. See 'Build-Up' Item 4. | M13: Star Rate | N13: Provisional - handover location | O13: =F13-K13 -> 4200 | P13: =IF(K13=0,"",(F13-K13)/K13) -> 0.66666667
A14: 5 | B14: Temporary Works, Construction Equipment, Tools and Site Support Facilities (Scaffolding, cranes, boom trucks, generators, trucks, small tools, temporary facilities and other equipment/resources required for execution of the works.) | C14: Ls | D14: 1 | E14: 504192.02 | F14: 504192.02 | G14: Percentage allocation of the lump sum; no quantities or rates. See 'Build-Up Comparison' | H14: Ls | I14: 1 | J14: ='Build-Up'!$F$89 -> 325350 | K14: =I14*J14 -> 325350 | L14: Plant, access, power and supplier attendance that the tank quotation excludes; the supplier's price is supply and installation, so GRP erectors are not priced (recorded scope of the offer, to be confirmed against the original). Helpers and plant are assessed phase by phase on the 'Programme' tab, Section 4, from material availability and activity dependencies: one helper gang while only Tank 1 material is planned on site, a second only while two fronts run (22-Oct to 14-Nov-2026), attendance for the submitted durations. No plant schedule has been submitted. See 'Build-Up' Item 5, 'Programme' Sections 3 to 5 and 'Build-Up Comparison' Section 4. | M14: Star Rate | N14: Assessed | O14: =F14-K14 -> 178842.02 | P14: =IF(K14=0,"",(F14-K14)/K14) -> 0.54969116
A15: TANKS
A16: 6 | B16: Supply and install of hot pressed non-insulated panel tank size:34(17+17) m(l) x 30.0 m(w) x 4.0 m(h) total capacity:4080 m3 | C16: No | D16: 2 | E16: 2763500 | F16: 5527000 | G16: Supplier quotation Al Mousa S04488 dated 09-Jul-2026 with Stalwart technical offer SS-07-26-1516 dated 03-Aug-2026 | H16: No | I16: 2 | J16: ='Build-Up'!$F$95 -> 2763500 | K16: =I16*J16 -> 5527000 | L16: The Contractor's adopted lowest quotation at net supplier cost, before the 5 per cent Overhead and Profit. It prices an insulated tank; the Engineer's (KEO) email of 30-Aug-2026 is that insulation is not required, so a lower price is expected. Quotation lapsed 08-Aug-2026; base panels not confirmed. See 'Build-Up' Item 6. | M16: Market Tested | N16: Provisional - quotation and specification | O16: =F16-K16 -> 0 | P16: =IF(K16=0,"",(F16-K16)/K16) -> 0
A17: 7 | B17: Testing, Commissioning, Hydrostatic/Leak Testing, System Integration and Handover | C17: Ls | D17: 2 | E17: 213200 | F17: 426400 | G17: Percentage allocation of the lump sum; no quantities or rates. See 'Build-Up Comparison' | H17: Ls | I17: 2 | J17: ='Build-Up'!$F$124 -> 51153 | K17: =I17*J17 -> 102306 | L17: One tank filled and the water re-used for the second, per the Engineer's (KEO) email of 30-Aug-2026; the Contractor's programme tests both tanks in parallel, which is shown beside this basis on the 'Programme' tab and not carried; the sequential test is fitted to the programme there, with Tank 1 tested early on a conditional method assumption and integrated commissioning after both tanks have passed and the tie-in is complete. A third-party factory acceptance test the Contractor is arranging is carried at nil (line 7.23) pending evidence that the Engineer requires it. Excludes the supplier's leak-test supervision (Item 6) and re-testing, which is the Contractor's obligation. Water source to be confirmed. See 'Build-Up' Item 7. | M17: Star Rate | N17: Provisional - water source and testing basis | O17: =F17-K17 -> 324094 | P17: =IF(K17=0,"",(F17-K17)/K17) -> 3.1678885
A18: 8 | B18: Supply, Fabrication and Installation of all Required TSE Tank Inlet/Outlet Piping, Instrumentation Connections, Supports and Accessories | C18: LS | D18: 1 | E18: 420000 | F18: 420000 | G18: Percentage allocation of the lump sum; no quantities or rates. See 'Build-Up Comparison' | H18: LS | I18: 1 | J18: ='Build-Up'!$F$150 -> 245200 | K18: =I18*J18 -> 245200 | L18: Provisional allowance priced to the RFP specification (GRP or ductile iron above DN150, uPVC below, butterfly isolation valves). The Contractor's procurement tracker of 29-Sep-2026 shows HDPE main-line pipe, a gate valve and a motorised butterfly valve being procured; the substitutions are not approved and are shown for information after line 8.21. No quantities exist: the pipework shop drawings were returned Code C and no take-off has been received. See 'Build-Up' Item 8. | M18: Star Rate | N18: Provisional - take-off pending | O18: =F18-K18 -> 174800 | P18: =IF(K18=0,"",(F18-K18)/K18) -> 0.71288744
B19: SUBTOTAL (SAR), VAT excluded | F19: =SUM(F8:F18) -> 7724092 | K19: =SUM(K8:K18) -> 6651836.6 | O19: =F19-K19 -> 1072255.5 | P19: =IF(K19=0,"",(F19-K19)/K19) -> 0.1611969
B20: Overhead and Profit, 5 per cent | F20: 386204.6 | K20: =ROUND(K19*0.05,2) -> 332591.83 | L20: 5 per cent as the Contractor's submission, within the Bill of Quantities Preamble cap. Covers head-office overheads (management, administration, finance, procurement) and profit only. Site staff, welfare, plant, power, water, security, insurance endorsement and close-out are priced in the items, whether one site or two. | O20: =F20-K20 -> 53612.77 | P20: =IF(K20=0,"",(F20-K20)/K20) -> 0.16119689
B21: TOTAL (SAR), VAT excluded | F21: =F19+F20 -> 8110296.6 | K21: =K19+K20 -> 6984428.4 | O21: =F21-K21 -> 1125868.2 | P21: =IF(K21=0,"",(F21-K21)/K21) -> 0.1611969
A22: Contractor columns are as submitted and unchanged. Assessed rates in column J are calculated on the 'Build-Up' tab; quantities are those submitted. Status 'Provisional' marks an item that depends on a confirmation still outstanding; the list is on the 'Build-Up Comparison' tab, Section 7. The Contractor's programme of 29-Sep-2026 is under the Engineer's approval and is not an agreed basis; the Contractor has been instructed and is on site, the instruction reference not having been supplied to the Cost Consultant.
A23: This assessment is preliminary. It establishes a reasonable commercial provision on the information available at 30-Sep-2026 and does not constitute agreement of the final Variation value.
A24: ="Changes from Rev 01 dated 17-Sep-2026 (SAR 6,921,685.64): every time-related period re-based from an assumed 3-month site period to the Contractor's programme of 29-Sep-2026 - site staff by role and phase and facilities for the site period "&"to the end of demobilisation (Item 1 and the generators in Item 5), helpers and plant from a phase-by-phase resource matrix built on material availability and activity dependencies, access equipment on the erection windows (Item 5); Item 7 "&"re-sequenced with the Engineer's sequential basis carried, commissioning staff reconciled to that sequence and a nil line added for the third-party factory test; sealant tools and fixings provisionally excluded as within the recorded Item 6"&" scope and third-party inspection visits removed as not required (5.12, 5.13, 7.12); PPE, survey and document control increased on the programme evidence (1.18, 2.3, 2.4); every line linked to its activities or site service on the 'Programm"&"e' tab; Item 8 re-described to the RFP specification with the Contractor's procured materials shown alongside; the Contractor's cost loading, cash flow and manpower histogram recorded as evidence on the 'Build-Up Comparison' tab. No rate ha"&"s moved. Net effect: SAR " & TEXT(K21-6921685.64,"#,##0.00;-#,##0.00") & " (" & TEXT((K21-6921685.64)/6921685.64,"0.0%;-0.0%") & ")." -> Changes from Rev 01 dated 17-Sep-2026 (SAR 6,921,685.64): every time-related period re-based from an assumed 3-month site period to the Contractor's programme of 29-Sep-2026 - site staff by role and phase and facilities for the site period to the end of demobilisation (Item 1 and the generators in Item 5), helpers and plant from a phase-by-phase resource matrix built on material availability and activity dependencies, access equipment on the erection windows (Item 5); Item 7 re-sequenced with the Engineer's sequential basis carried, commissioning staff reconciled to that sequence and a nil line added for the third-party factory test; sealant tools and fixings provisionally excluded as within the recorded Item 6 scope and third-party inspection visits removed as not required (5.12, 5.13, 7.12); PPE, survey and document control increased on the programme evidence (1.18, 2.3, 2.4); every line linked to its activities or site service on the 'Programme' tab; Item 8 re-described to the RFP specification with the Contractor's procured materials shown alongside; the Contractor's cost loading, cash flow and manpower histogram recorded as evidence on the 'Build-Up Comparison' tab. No rate has moved. Net effect: SAR 62,742.75 (0.9%).

Sheet Build-Up
A1: ASSESSED RATE BUILD-UPS
A2: TSE Irrigation Storage Tanks and Associated Pipeworks (RFP-027) - Contract QPMO-410-CT-05958
A3: Contractor: SAMA Construction | Engineer: KEO | Cost Consultant: WT Partnership | Rev 02, 30-Sep-2026
A4: How to read this tab: each item on the 'Assessment' tab whose rate is assessed rather than quoted is built up here as quantity x rate, with its basis beside it. Item totals carry to column J of the 'Assessment' tab. Quantities shown in column D as links to the 'Programme' tab are derived from the Contractor's programme of 29-Sep-2026 on the basis carried there (Basis B); the same lines on the programme exactly as submitted (Basis A) are on the 'Programme' tab, Section 4. Rates marked 'assumption' are working assumptions pending the Contractor's substantiation. All amounts exclude VAT.
A6: ITEM 1 - SITE MOBILISATION, TEMPORARY FACILITIES AND WELFARE
A7: The tank site is in the lower plateau, outside the D-18 site boundary. Site management, welfare, water, security, insurance cover and close-out are therefore assessed as a separate establishment. Periods are taken from the Contractor's programme of 29-Sep-2026 ('Programme' tab, Section 3): site staff, transport and facilities for the site period D1, mobilisation to the end of demobilisation, with the post-demobilisation completion inspection priced at 1.22 and 1.23. The programme is under the Engineer's approval and is not an agreed basis; the end of the site period is set by the external readiness milestone of 03-Dec-2026 and the tie-in, sequential testing, commissioning and demobilisation that follow. Site staff are assessed role by role with their phase duties on the 'Programme' tab, Section 4. Design and engineering resources are shared with the main Contract (Item 2). Power is in Item 5. The tank supplier's price includes the installer's own mobilisation; the foundations and steel base frames are existing.
A8: Ref | B8: Description | C8: Unit | D8: Qty | E8: Rate (SAR) | F8: Amount (SAR) | G8: Basis
A9: 1.1 | B9: Site engineer - dedicated to the tank site | C9: month | D9: =Programme!$G$113 -> 4.1 | E9: 12000 | F9: =D9*E9 -> 49200 | G9: Dedicated for the site period, mobilisation to the end of demobilisation, with the phase duties set out on the 'Programme' tab, Section 4, role R1. Assessed market rate, Riyadh, Sep-2026 - assumption pending the Contractor's substantiation
A10: 1.2 | B10: HSE officer - dedicated | C10: month | D10: =Programme!$G$114 -> 4.1 | E10: 10000 | F10: =D10*E10 -> 41000 | G10: Dedicated for the site period with the phase duties at 'Programme' tab, Section 4, role R2. Assessed market rate, Riyadh, Sep-2026 - assumption pending the Contractor's substantiation
A11: 1.3 | B11: QA/QC inspector - dedicated (daily inspections, ITPs and WIRs during erection) | C11: month | D11: =Programme!$G$115 -> 3.7 | E11: 10000 | F11: =D11*E11 -> 37000 | G11: From the start of dismantling to completion of testing and commissioning only ('Programme' tab, Section 4, role R3); not during mobilisation or demobilisation. Assessed market rate, Riyadh, Sep-2026 - assumption pending the Contractor's substantiation
A12: 1.4 | B12: Works foreman - dedicated | C12: month | D12: =Programme!$G$116 -> 4.1 | E12: 8000 | F12: =D12*E12 -> 32800 | G12: Dedicated for the site period: the Contractor's own labour is on site from mobilisation to demobilisation ('Programme' tab, Section 4, role R4). Assessed market rate, Riyadh, Sep-2026 - assumption pending the Contractor's substantiation
A13: 1.5 | B13: Storekeeper / timekeeper | C13: month | D13: =Programme!$G$117 -> 3.3 | E13: 4000 | F13: =D13*E13 -> 13200 | G13: From the first delivery to completion of testing only ('Programme' tab, Section 4, role R5). Assessed market rate, Riyadh, Sep-2026 - assumption pending the Contractor's substantiation
A14: 1.6 | B14: Site office porta cabin, air-conditioned, rental with electricity connection and maintenance | C14: month | D14: =Programme!$G$118 -> 4.1 | E14: 2200 | F14: =D14*E14 -> 9020 | G14: Site period D1 on the 'Programme' tab, Section 3 (activity QCD18TSEMOB1250, 22-Aug-2026, to activity QCD18TSEDMOB1020, 24-Dec-2026). Assessed market rate, Riyadh, Sep-2026 - assumption pending the Contractor's substantiation
A15: 1.7 | B15: Rest and welfare porta cabin, air-conditioned, rental with electricity connection and maintenance | C15: month | D15: =Programme!$G$119 -> 4.1 | E15: 2200 | F15: =D15*E15 -> 9020 | G15: Site period D1 on the 'Programme' tab, Section 3 (activity QCD18TSEMOB1250, 22-Aug-2026, to activity QCD18TSEDMOB1020, 24-Dec-2026). Assessed market rate, Riyadh, Sep-2026 - assumption pending the Contractor's substantiation
A16: 1.8 | B16: WC unit, rental with servicing | C16: month | D16: =Programme!$G$120 -> 4.1 | E16: 1300 | F16: =D16*E16 -> 5330 | G16: Site period D1 on the 'Programme' tab, Section 3 (activity QCD18TSEMOB1250, 22-Aug-2026, to activity QCD18TSEDMOB1020, 24-Dec-2026). Assessed market rate, Riyadh, Sep-2026 - assumption pending the Contractor's substantiation
A17: 1.9 | B17: Site water supply - tankered deliveries for welfare and general site use, whole period | C17: delivery | D17: =Programme!$G$121 -> 36 | E17: 350 | F17: =D17*E17 -> 12600 | G17: Two 10 m3 deliveries a week for the weeks of the site period D1 on the 'Programme' tab, Section 3; no mains water at the tank site. Assessed market rate, Riyadh, Sep-2026 - assumption pending the Contractor's substantiation
A18: 1.10 | B18: Site water storage tank, hire | C18: month | D18: =Programme!$G$122 -> 4.1 | E18: 350 | F18: =D18*E18 -> 1435 | G18: Site period D1 on the 'Programme' tab, Section 3 (activity QCD18TSEMOB1250, 22-Aug-2026, to activity QCD18TSEDMOB1020, 24-Dec-2026). Assessed market rate, Riyadh, Sep-2026 - assumption pending the Contractor's substantiation
A19: 1.11 | B19: Storage containers, 2 No. for the panel storage window (RFP Scope of Works, work package 1 - pre-construction and setup: safe storage of panels) | C19: container-month | D19: =Programme!$G$123 -> 5.6 | E19: 1200 | F19: =D19*E19 -> 6720 | G19: 2 No. containers for the storage window D7 on the 'Programme' tab, Section 3, first delivery to the Tank 2 roof finish. Assessed market rate, Riyadh, Sep-2026 - assumption pending the Contractor's substantiation
A20: 1.12 | B20: Workforce transport to the tank site, daily bus | C20: month | D20: =Programme!$G$124 -> 4.1 | E20: 4000 | F20: =D20*E20 -> 16400 | G20: Separate site outside the D-18 boundary; site period D1 on the 'Programme' tab, Section 3. Assessed market rate, Riyadh, Sep-2026 - assumption pending the Contractor's substantiation
A21: 1.13 | B21: Watchman for the tank site | C21: month | D21: =Programme!$G$125 -> 4.1 | E21: 4500 | F21: =D21*E21 -> 18450 | G21: Site period D1 on the 'Programme' tab, Section 3. Included pending confirmation whether the Employer's security covers the lower plateau; delete if it does. Assessed market rate, Riyadh, Sep-2026 - assumption pending the Contractor's substantiation
A22: 1.14 | B22: Mobilisation - flatbed trips delivering cabins, containers and small plant | C22: trip | D22: 5 | E22: 1250 | F22: =D22*E22 -> 6250 | G22: 5 trips retained: the programme gives no trip count (activity QCD18TSEMOB1240, mobilisation, 5 working days). Assessed market rate, Riyadh, Sep-2026 - assumption pending the Contractor's substantiation
A23: 1.15 | B23: Demobilisation - flatbed trips removing cabins, containers and small plant | C23: trip | D23: 5 | E23: 1250 | F23: =D23*E23 -> 6250 | G23: 5 trips retained: the programme gives no trip count (activity QCD18TSEDMOB1020, demobilisation, 7 working days). Assessed market rate, Riyadh, Sep-2026 - assumption pending the Contractor's substantiation
A24: 1.16 | B24: Site clean-up on demobilisation, 4 No. x 3 days | C24: man-day | D24: 12 | E24: 150 | F24: =D24*E24 -> 1800 | G24: Assessed market rate, Riyadh, Sep-2026 - assumption pending the Contractor's substantiation
A25: 1.17 | B25: Insurance endorsement - extension of the Contractor's All Risks and third-party liability cover to the tank site | C25: item | D25: 1 | E25: 13000 | F25: =D25*E25 -> 13000 | G25: The Contract insurances cover the Site as defined; the tank site is outside it. Assumed at 0.2 per cent of the works value - the insurer's endorsement premium is to be substantiated by the Contractor
A26: 1.18 | B26: Personal protective equipment, full sets | C26: No | D26: 20 | E26: 350 | F26: =D26*E26 -> 7000 | G26: Peak Contractor headcount from the resource matrix ('Programme' tab, Section 4): two helper gangs and the offloading gang (up to 14), five site staff and the pipework crew - about 20 sets; the supplier's crews wear their own. Assessed market rate, Riyadh, Sep-2026 - assumption pending the Contractor's substantiation
A27: 1.19 | B27: Site safety signage and notice boards | C27: No | D27: 12 | E27: 150 | F27: =D27*E27 -> 1800 | G27: HSE signage at the work area, distinct from the traffic signs at 1.20. Assessed market rate, Riyadh, Sep-2026 - assumption pending the Contractor's substantiation
A28: 1.20 | B28: Work-zone traffic signs up to 0.5 m2, supplied, installed, maintained and removed | C28: No | D28: 12 | E28: 1479.63 | F28: =D28*E28 -> 17755.56 | G28: Agreed rate under RFP-021 (assessment dated 30-Jun-2026), derived from RFP-002A, Sign World quotation 6512 - an agreed rate under Sub-Clause 13.3.4(a) of the Conditions of Contract
A29: 1.21 | B29: Concrete Jersey barriers - temporary hire for the works period, delivered, placed and removed | C29: Lm | D29: 100 | E29: 100 | F29: =D29*E29 -> 10000 | G29: Hire basis. The Bill of Quantities Part 9 rate (SAR 396/Lm) is for permanent supply and is not applied. 100 Lm assumed - to be confirmed against the work-area layout
A30: 1.22 | B30: Close-out at the tank site after demobilisation - completion inspection, correction list and warranties collation - site engineer | C30: day | D30: 3 | E30: 550 | F30: =D30*E30 -> 1650 | G30: 3 days after demobilisation: the Engineer's completion inspection, the correction list and the warranties collation. Reduced from 8 days because the site engineer's monthly period at 1.1 now runs to the end of demobilisation and the programmed close-out activity (QCD18TSEDMOB3020, 17 to 24-Dec-2026) falls inside it. Test records, ITP/WIR close-out and as-built drawings are in Item 7 (7.20 and 7.21), not here. Assessed market rate, Riyadh, Sep-2026 - assumption pending the Contractor's substantiation
A31: 1.23 | B31: Close-out at the tank site - document controller | C31: day | D31: 4 | E31: 500 | F31: =D31*E31 -> 2000 | G31: Assessed market rate, Riyadh, Sep-2026 - assumption pending the Contractor's substantiation
B32: TOTAL ITEM 1 - carried to 'Assessment'!J8 | F32: =SUM(F9:F31) -> 319680.56
A34: ITEM 2 - DESIGN AND ENGINEERING
A35: Tank structural design sits with the supplier (Stalwart technical offer SS-07-26-1516 dated 03-Aug-2026). All documentation is issued electronically via Aconex; no printing is included.
A36: Ref | B36: Description | C36: Unit | D36: Qty | E36: Rate (SAR) | F36: Amount (SAR) | G36: Basis
A37: 2.1 | B37: Design engineer - coordination, review of supplier calculations, method statements, ITPs | C37: month | D37: 2 | E37: 15000 | F37: =D37*E37 -> 30000 | G37: 2 months retained: the programme shows shop drawings 07 to 25-Aug-2026 (activities QCD18TSEENG1240 and 1250) with resubmissions to 29-Sep-2026 and the pipework shop drawings still in preparation, consistent with the period assessed. Assessed market rate, Riyadh, Sep-2026 - assumption pending the Contractor's substantiation
A38: 2.2 | B38: CAD draughtsman - shop drawings and design-stage submittals | C38: month | D38: 1.5 | E38: 8000 | F38: =D38*E38 -> 12000 | G38: 1.5 months retained on the same programme evidence as 2.1. As-built drawings at close-out are line 7.21. Assessed market rate, Riyadh, Sep-2026 - assumption pending the Contractor's substantiation
A39: 2.3 | B39: Dimensional and verticality survey of the erected tanks and as-built pick-up - 2-man crew with instrument | C39: crew-day | D39: 6 | E39: 1500 | F39: =D39*E39 -> 9000 | G39: Survey and levelling of the existing foundation (activity QCD18TSECONSL1050, 07 to 13-Sep-2026, cost-loaded by the Contractor at SAR 5,000.00) assessed at 3 crew-days for an existing base frame, plus a dimensional and verticality survey of each erected tank, 1.5 crew-days each (RFP Scope of Works, work package 3). Not setting out: the steel base frames are already installed on concrete supports (site photograph, Aug-2026). Assessed market rate, Riyadh, Sep-2026 - assumption pending the Contractor's substantiation
A40: 2.4 | B40: Submittal administration - document controller | C40: day | D40: 8 | E40: 500 | F40: =D40*E40 -> 4000 | G40: The programme carries 19 deliverable and submittal activities plus the material approval and inspection requests; 8 days of document control, doubled from the previous revision on that evidence. Assessed market rate, Riyadh, Sep-2026 - assumption pending the Contractor's substantiation
B41: TOTAL ITEM 2 - carried to 'Assessment'!J10 | F41: =SUM(F37:F40) -> 55000
A43: ITEM 3 - SAFE DISMANTLING OF DAMAGED TSE TANK-1
...

Sheet Build-Up Comparison
A1: CONTRACTOR'S BUILD-UP COMPARED WITH THE ASSESSMENT
A2: TSE Irrigation Storage Tanks and Associated Pipeworks (RFP-027) - Contract QPMO-410-CT-05958
A3: Contractor: SAMA Construction | Engineer: KEO | Cost Consultant: WT Partnership | Rev 02, 30-Sep-2026
A4: The Contractor was asked on 25-Aug-2026 to substantiate the lump-sum items in its proposal. It submitted a rate build-up for Items 1, 5, 7 and 8. This tab sets each component of that submission against the assessed build-up on the 'Build-Up' tab and records whether the amount claimed is supported. Column F sets against each of the Contractor's components the 'Build-Up' lines assessed for the same work, so that the two build-ups can be read side by side and both columns foot to the item totals. All amounts exclude VAT.
A6: 1. SUMMARY
A7: Item | B7: Description | E7: Claimed by the Contractor (SAR) | F7: Assessed (SAR) | G7: Difference (SAR) | H7: Conclusion
A8: 1 | B8: Site mobilisation, temporary facilities and welfare | E8: =Assessment!$F$8 -> 680000 | F8: =Assessment!$K$8 -> 319680.56 | G8: =E8-F8 -> 360319.44 | H8: Not substantiated. A separate site establishment is allowable and is assessed in Section 3 of this tab.
A9: 5 | B9: Temporary works, construction equipment and site support | E9: =Assessment!$F$14 -> 504192.02 | F9: =Assessment!$K$14 -> 325350 | G9: =E9-F9 -> 178842.02 | H9: Not substantiated. No plant numbers, periods or rates; includes a contingency line. See Section 4 of this tab.
A10: 7 | B10: Testing, commissioning and handover | E10: =Assessment!$F$17 -> 426400 | F10: =Assessment!$K$17 -> 102306 | G10: =E10-F10 -> 324094 | H10: Not substantiated. No volumes, counts or rates; includes re-testing. See Section 5 of this tab.
A11: 8 | B11: Piping, instrumentation, supports and accessories | E11: =Assessment!$F$18 -> 420000 | F11: =Assessment!$K$18 -> 245200 | G11: =E11-F11 -> 174800 | H11: Not substantiated. No quantities; take-off outstanding. See Section 6 of this tab.
B12: Total of the four items submitted | E12: =SUM(E8:E11) -> 2030592 | F12: =SUM(F8:F11) -> 992536.56 | G12: =E12-F12 -> 1038055.5 | H12: The submission does not change the assessment.
A13: Items 2 (Design and engineering, SAR 85,000.00) and 4 (Removal and disposal, SAR 10,500.00) were also requested and have not been submitted.
A15: 2. HOW THE CONTRACTOR'S BUILD-UP IS CONSTRUCTED
A16: - Each amount is the claimed lump sum multiplied by an assumed percentage, for example 25 per cent x SAR 504,192.02. The percentages are set to total 100 per cent, so each sheet returns the figure it started from.
A17: - No quantities and no unit rates are stated in any of the four sheets.
A18: - Plant is named without capacity, number, hire period or rate. Labour is given as ranges such as "approx. 4-6 crew", not as man-days.
A19: - The Item 1 percentages are a weighting of 83 parts (20, 6, 8, 12, 8, 7, 10 and 12), which is why they carry six decimal places.
A20: - The submission allocates the sums already claimed; it does not build them up, and it does not allow the quantities and rates to be substantiated as Sub-Clause 12.3.2 of the Conditions of Contract requires.
A22: 3. ITEM 1 - SITE MOBILISATION, TEMPORARY FACILITIES AND WELFARE
A23: The tank site is in the lower plateau, outside the D-18 site boundary, so a separate site establishment is allowable. The Contractor's components are the Contract Preliminaries headings restated with percentages; none is built up as quantity x rate.
A24: Ref | B24: Component as submitted by the Contractor | C24: Basis stated by the Contractor | D24: % of item | E24: Amount claimed (SAR) | F24: Assessed (SAR) | G24: Difference (SAR) | H24: Assessment comment
A25: 1.1 | B25: Heavy equipment mobilization/demobilization (cranes, trucks, machinery transport to/from site) | C25: Site establishment cost driver for the scale of works | D25: 0.240964 | E25: 163855.52 | F25: ='Build-Up'!$F$22 -> 6250 | G25: =E25-F25 -> 157605.52 | H25: Assessed as mobilisation trips for cabins, containers and small plant ('Build-Up' 1.14); demobilisation is assessed against the Contractor's line 1.8 in this table. No trips or rates stated. The tank installer's own mobilisation is within the supplier quotation adopted under Item 6 (Al Mousa S04488 dated 09-Jul-2026).
A26: 1.2 | B26: Construction Facilities - welfare & First Aid facilities | C26: Per Contract Preliminaries: welfare and First Aid facilities provision at site | D26: 0.072289 | E26: 49156.52 | F26: ='Build-Up'!$F$14+'Build-Up'!$F$15+'Build-Up'!$F$16 -> 23370 | G26: =E26-F26 -> 25786.52 | H26: Assessed as a site office cabin, a welfare cabin and a WC unit for 3 months ('Build-Up' 1.6 to 1.8). No units, period or rate stated.
A27: 1.3 | B27: Vehicular Access & Parking (traffic signs, safety barriers, etc.) | C27: Per Contract: Vehicular Access and Parking, including traffic signs, safety barriers, etc. | D27: 0.096386 | E27: 65542.48 | F27: ='Build-Up'!$F$28+'Build-Up'!$F$29 -> 27755.56 | G27: =E27-F27 -> 37786.92 | H27: Assessed as 12 traffic signs at the RFP-021 agreed rate and 100 Lm of hired barriers ('Build-Up' 1.20 and 1.21). No quantities stated.
A28: 1.4 | B28: Personnel mobilization (transport, camp/accommodation setup, induction) | C28: Personnel mobilization to site | D28: 0.144578 | E28: 98313.04 | F28: ='Build-Up'!$F$20 -> 16400 | G28: =E28-F28 -> 81913.04 | H28: Assessed as daily workforce transport to the tank site ('Build-Up' 1.12). Camp and accommodation set-up is not allowed: the workforce is already employed and accommodated under the Contract.
A29: 1.5 | B29: Temporary utilities connection (power distribution, water supply to site) | C29: Standard site establishment item | D29: 0.096386 | E29: 65542.48 | F29: ='Build-Up'!$F$17+'Build-Up'!$F$18 -> 14035 | G29: =E29-F29 -> 51507.48 | H29: Assessed as tankered site water and a storage tank for the whole period ('Build-Up' 1.9 and 1.10). Power is assessed against the Contractor's Item 5, line 5.4 (generators), in Section 4 of this tab, and is not repeated here. No basis stated.
A30: 1.6 | B30: Permits, insurance, HSE setup & signage | C30: Standard preliminary cost | D30: 0.084337 | E30: 57349.16 | F30: ='Build-Up'!$F$10+'Build-Up'!$F$25+'Build-Up'!$F$26+'Build-Up'!$F$27 -> 62800 | G30: =E30-F30 -> -5450.84 | H30: Assessed as a dedicated HSE officer, an insurance endorsement extending the Contract cover to the tank site, PPE and site safety signage ('Build-Up' 1.2 and 1.17 to 1.19). Traffic signs are against line 1.3. No basis stated.
A31: 1.7 | B31: Close out (Completion and Correction List, Warranties, Project Record Documents) | C31: Per Contract Preliminaries Item 22: Close out documentation | D31: 0.120482 | E31: 81927.76 | F31: ='Build-Up'!$F$30+'Build-Up'!$F$31 -> 3650 | G31: =E31-F31 -> 78277.76 | H31: Assessed as a separate completion procedure for the tank site: inspections, correction list and warranties ('Build-Up' 1.22 and 1.23). Test records, ITP/WIR close-out and as-built drawings are assessed under Item 7 and not repeated. No resource or duration stated.
A32: 1.8 | B32: Demobilization at completion (equipment removal, site clean-up, facility removal) | C32: Mirrors mobilization scope at close-out | D32: 0.144578 | E32: 98313.04 | F32: ='Build-Up'!$F$23+'Build-Up'!$F$24 -> 8050 | G32: =E32-F32 -> 90263.04 | H32: Assessed as demobilisation trips and site clean-up ('Build-Up' 1.15 and 1.16). No trips, labour or rates stated.
B33: Assessed but not identified in the Contractor's build-up: site supervision, storage and security | E33: 0 | F33: ='Build-Up'!$F$9+'Build-Up'!$F$11+'Build-Up'!$F$12+'Build-Up'!$F$13+'Build-Up'!$F$19+'Build-Up'!$F$21 -> 157370 | G33: =E33-F33 -> -157370 | H33: Site engineer, QA/QC inspector, works foreman, storekeeper, storage containers and watchman ('Build-Up' 1.1, 1.3 to 1.5, 1.11 and 1.13). The Contractor's manpower schedule places site staff in general overheads and prices none here.
B34: Totals for this item | E34: =SUM(E25:E33) -> 680000 | F34: =SUM(F25:F33) -> 319680.56 | G34: =E34-F34 -> 360319.44 | H34: Column F foots to the item total on the 'Assessment' tab, row 8.
A35: The manpower schedule submitted with Item 1 states that the full-time roles' 151-day cost and the part-time allocations are carried under the Contractor's general overheads and preliminaries, and that it "does not reprice Item 1's Est. % / Est. Amount values". It provides no support for the amount claimed. The 151-day duration is asserted without a programme.
A37: 4. ITEM 5 - TEMPORARY WORKS, CONSTRUCTION EQUIPMENT AND SITE SUPPORT
A38: The stated basis for six of the eight lines is a quotation of the RFP item description. Restating the description does not substantiate the price.
A39: Ref | B39: Component as submitted by the Contractor | C39: Basis stated by the Contractor | D39: % of item | E39: Amount claimed (SAR) | F39: Assessed (SAR) | G39: Difference (SAR) | H39: Assessment comment
A40: 5.1 | B40: Scaffolding & access platforms (for tank erection/bracing works) | C40: Per RFP wording: 'Scaffolding' | D40: 0.15 | E40: 75628.803 | F40: ='Build-Up'!$F$76+'Build-Up'!$F$77+'Build-Up'!$F$78+'Build-Up'!$F$79 -> 66520 | G40: =E40-F40 -> 9108.803 | H40: Assessed as 1,024 m2 of perimeter scaffold, access towers and podium steps ('Build-Up' 5.3 to 5.6). No area, period or rate stated.
A41: 5.2 | B41: Mobile crane(s) rental for tank panel erection (duration-based) | C41: Per RFP wording: 'cranes' | D41: 0.25 | E41: 126048.01 | F41: ='Build-Up'!$F$75 -> 55800 | G41: =E41-F41 -> 70248.005 | H41: Assessed as a telehandler for the hire days on the 'Programme' tab, Section 4 ('Build-Up' 5.2): the existing base frames and 4 m panel height do not call for a mobile crane. The Contractor's plant schedule is awaited. No capacity, units, period or rate stated.
A42: 5.3 | B42: Boom trucks / man-lifts for elevated works | C42: Per RFP wording: 'boom trucks' | D42: 0.12 | E42: 60503.042 | F42: ='Build-Up'!$F$74 -> 52800 | G42: =E42-F42 -> 7703.0424 | H42: Assessed as a boom truck for the hire days on the 'Programme' tab, Section 4 ('Build-Up' 5.1). No units, period or rate stated.
A43: 5.4 | B43: Generators - rental & fuel for site power | C43: Per RFP wording: 'generators' | D43: 0.1 | E43: 50419.202 | F43: ='Build-Up'!$F$80+'Build-Up'!$F$81+'Build-Up'!$F$88 -> 69200 | G43: =E43-F43 -> -18780.798 | H43: Assessed as a 100 kVA works set by day and a 30 kVA welfare set running continuously, both for the whole period with fuel, and distribution boards ('Build-Up' 5.7, 5.8 and 5.15). All site power is assessed here; none is assessed under the Contractor's Item 1, line 1.5 (temporary utilities), in Section 3 of this tab, so there is no double count. No set size, period or fuel basis stated.
A44: 5.5 | B44: Site trucks & transport (materials, spoil, deliveries) | C44: Per RFP wording: 'trucks' | D44: 0.1 | E44: 50419.202 | F44: ='Build-Up'!$F$82 -> 12300 | G44: =E44-F44 -> 38119.202 | H44: Assessed as a site pick-up for 3 months ('Build-Up' 5.9). No vehicles, period or rate stated.
...

Sheet Programme
A1: THE CONTRACTOR'S PROGRAMME - ACTIVITY DATA AND DURATION BASES
A2: TSE Irrigation Storage Tanks and Associated Pipeworks (RFP-027) - Contract QPMO-410-CT-05958
A3: Contractor: SAMA Construction | Engineer: KEO | Cost Consultant: WT Partnership | Rev 02, 30-Sep-2026
A4: How to read this tab: Section 1 records the status of the programme and of the instruction. Section 2 is the working calendar taken from the programme file. Section 3 sets the programme's windows as submitted beside the basis carried, every date derived by formula from the activity data in Section 7. Section 4 is the resource matrix: for each phase, what material is on site, which activities are active and what they depend on, whose crew does the work, which Contractor helpers, plant and site staff are needed, and where each is priced. Section 5 lists each 'Build-Up' line whose quantity is taken from this tab, with the programme exactly as submitted beside the basis carried; the carried quantity is the one linked into column D of the 'Build-Up' tab. Section 6 links every 'Build-Up' line to its activities or site service. All amounts exclude VAT.
A6: 1. STATUS OF THE PROGRAMME AND OF THE INSTRUCTION
A7: Programme: baseline schedule 'QC05958-BSL01THF-TSE-Final' (QC05958-BSL01THF-TSE.xer, data date 01-Jul-2026, 81 activities, cost-loaded to the proposal value of SAR 8,110,296.62 including 5 per cent Overhead and Profit), submitted by the Contractor to the Engineer on 12-Sep-2026 and issued to the Cost Consultant on 29-Sep-2026 with a cost S-curve, a monthly cash flow, a weekly direct-manpower histogram and a two-week look-ahead (data date 28-Sep-2026). Status at 30-Sep-2026: under the Engineer's approval process - returned as acceptable with minor comments, a procurement schedule being required; not approved. The programme is therefore evidence of the Contractor's intended sequence and durations, not an agreed basis; every line on the 'Build-Up' tab that relies on it says so.
A8: Instruction: the Contractor has been instructed to proceed and is on site (the existing tank is dismantled and the Tank 1 base panels are being received). The instruction reference and date have not been supplied to the Cost Consultant and are to be recorded on the 'Project Info' tab when received. RFP-027 dated 28-Jun-2026 stated that it was not itself an instruction to proceed. The instruction affects entitlement and the certification route, not the assessed value.
A9: Use made of the programme: (i) the site period is taken as submitted, its end being governed by the external milestone 'SAJCO Readiness for Tie-In Connections' on 03-Dec-2026 and the tie-in, sequential testing, commissioning and demobilisation that follow it; (ii) the erection windows and their durations are taken as submitted, and the labour and plant that attend them are assessed for those durations (Section 4); (iii) testing is carried on the Engineer's basis of 30-Aug-2026 (one tank filled, water re-used for the second), fitted to the submitted dates. Slippage against the baseline shown in the look-ahead (Tank 1 base panels forecast to start 30-Sep-2026 against 12-Sep-2026 programmed) is delivery-driven and adds nothing to the assessment. Dates after the look-ahead data date of 28-Sep-2026 are forecasts, not actuals.
A11: 2. WORKING CALENDAR
A12: Ref | B12: Calendar item | C12: Value | I12: Source
A13: C1 | B13: Working week for site activities | C13: 6 days, Friday non-working, 10 hours a day | I13: Calendar 'QIC 6 Days 10 Hrs' in QC05958-BSL01THF-TSE.xer, applied to every site activity; the approval activities use 'QIC 5 Days 10 Hrs' and the milestones 'QIC 7 Days 10 Hrs'
A14: C2 | B14: Non-working day within the works period | C14: 46288 | I14: Calendar exception in QC05958-BSL01THF-TSE.xer (Saudi National Day). Every working-day formula on this tab excludes Fridays and this date
A15: C3 | B15: Calendar days per month used to convert periods to months | C15: 30.4 | I15: Average month (365 days / 12); months are rounded to one decimal place
A17: 3. PROGRAMME WINDOWS - A: AS SUBMITTED; B: AS CARRIED (SUBMITTED ERECTION DATES, SEQUENTIAL TESTING)
A18: Column A reproduces the submitted programme, including its parallel testing. Column B is the basis carried: the erection dates exactly as submitted - no activity is compressed - with the Engineer's sequential testing fitted after the tank each test needs, and demobilisation following completion. Both columns are derived by formula from the activity data in Section 6 and the calendar in Section 2. The resources that each window carries are assessed in Section 4; the site period is set by the external readiness milestone of 03-Dec-2026 and the tie-in, testing, commissioning and demobilisation that follow it.
A19: Ref | B19: Window | C19: Start - Basis A | D19: Finish - Basis A | E19: Days - A | F19: Start - Basis B | G19: Finish - Basis B | H19: Days - B | I19: Derivation and source
A20: P1 | B20: Mobilisation and site establishment (calendar days) | C20: =$C$368 -> 46256 | D20: =$D$369 -> 46260 | E20: =D20-C20+1 -> 5 | F20: =C20 -> 46256 | G20: =D20 -> 46260 | H20: =E20 -> 5 | I20: Activities QCD18TSEMOB1240 and QCD18TSEMOB1250, 22 to 26-Aug-2026, QC05958-BSL01THF-TSE.xer. Mobilisation has taken place (the existing tank is dismantled)
A21: P2 | B21: Dismantling of the existing damaged Tank-1 (calendar days) | C21: =$C$371 -> 46261 | D21: =$D$374 -> 46277 | E21: =D21-C21+1 -> 17 | F21: =C21 -> 46261 | G21: =D21 -> 46277 | H21: =E21 -> 17 | I21: Activities QCD18TSECONDSM1020 to 1030, 27-Aug to 12-Sep-2026, QC05958-BSL01THF-TSE.xer. Complete per the look-ahead of 29-Sep-2026 (data date 28-Sep-2026); the completion date is not recorded, so the programmed dates are kept. Dismantling, segregation and loading are within the Item 3 quotation
A22: P3 | B22: Tank 1 - base panels (working days) | C22: =$C$380 -> 46277 | D22: =$D$380 -> 46300 | E22: =NETWORKDAYS.INTL(C22,D22,"0000100",$C$14) -> 20 | F22: =C22 -> 46277 | G22: =D22 -> 46300 | H22: =E22 -> 20 | I22: Activity QCD18TSECONT1INS1020, 12-Sep to 05-Oct-2026, 20 working days, linked to the partial delivery QCD18TSEPRC1120 (08-Sep to 03-Oct-2026, start 3 days after, finish 2 days after). Taken as submitted. The identical work on Tank 2 (QCD18TSECONT2INS1020) is programmed at 6 working days - a productivity cross-check only (Section 4, S5). The look-ahead forecasts the start as 30-Sep-2026, delivery-driven, the Contractor's risk
A23: P4 | B23: Tank 1 - wall panels (working days) | C23: =$C$386 -> 46301 | D23: =$D$386 -> 46319 | E23: =NETWORKDAYS.INTL(C23,D23,"0000100",$C$14) -> 16 | F23: =C23 -> 46301 | G23: =D23 -> 46319 | H23: =E23 -> 16 | I23: Activity QCD18TSECONT1INS1030, 06 to 24-Oct-2026, 16 working days, linked to the wall-panel delivery QCD18TSEPRC1170 (start 2 days after, finish 4 days after). Taken as submitted; Tank 2 walls (QCD18TSECONT2INS1030) 12 working days, cross-check only
A24: P5 | B24: Tank 1 - bracing (working days) | C24: =$C$387 -> 46303 | D24: =$D$387 -> 46324 | E24: =NETWORKDAYS.INTL(C24,D24,"0000100",$C$14) -> 19 | F24: =C24 -> 46303 | G24: =D24 -> 46324 | H24: =E24 -> 19 | I24: Activity QCD18TSECONT1INS1060, 08 to 29-Oct-2026, 19 working days, starting 2 days after the walls and finishing 5 days after them. Taken as submitted; Tank 2 bracing 15 working days, cross-check only
A25: P6 | B25: Tank 1 - roof supports and ladder (working days) | C25: =$C$393 -> 46326 | D25: =$D$393 -> 46330 | E25: =NETWORKDAYS.INTL(C25,D25,"0000100",$C$14) -> 5 | F25: =C25 -> 46326 | G25: =D25 -> 46330 | H25: =E25 -> 5 | I25: Activity QCD18TSECONT1INS1040, 31-Oct to 04-Nov-2026, 5 working days, the same as Tank 2
A26: P7 | B26: Tank 1 - roof panels (working days) | C26: =$C$397 -> 46331 | D26: =$D$397 -> 46337 | E26: =NETWORKDAYS.INTL(C26,D26,"0000100",$C$14) -> 6 | F26: =C26 -> 46331 | G26: =D26 -> 46337 | H26: =E26 -> 6 | I26: Activity QCD18TSECONT1INS1050, 05 to 11-Nov-2026, 6 working days, the same as Tank 2
A27: Ref | B27: Window | C27: Start - Basis A | D27: Finish - Basis A | E27: Days - A | F27: Start - Basis B | G27: Finish - Basis B | H27: Days - B | I27: Derivation and source
A28: P8 | B28: Tank 1 - mechanical works: nozzles, level transmitter, pipes and fittings (working days) | C28: =$C$398 -> 46335 | D28: =$D$400 -> 46342 | E28: =NETWORKDAYS.INTL(C28,D28,"0000100",$C$14) -> 7 | F28: =C28 -> 46335 | G28: =D28 -> 46342 | H28: =E28 -> 7 | I28: Activities QCD18TSECONT1MW2050, 2060 and 2055, 09 to 16-Nov-2026. Nozzles and internals are within the supplier's scope (Item 6); the level transmitter and the pipes and fittings are priced supplied and installed under Item 8
A29: P9 | B29: Tank 2 - base panels (working days) | C29: =$C$390 -> 46317 | D29: =$D$390 -> 46323 | E29: =NETWORKDAYS.INTL(C29,D29,"0000100",$C$14) -> 6 | F29: =C29 -> 46317 | G29: =D29 -> 46323 | H29: =E29 -> 6 | I29: Activity QCD18TSECONT2INS1020, 22 to 28-Oct-2026, 6 working days, starting 2 working days after the Tank 2 delivery begins (QCD18TSEPRC1210, 20-Oct-2026); from here the two tanks are erected on two fronts at once until 17-Nov-2026
A30: P10 | B30: Tank 2 - wall panels (working days) | C30: =$C$392 -> 46324 | D30: =$D$392 -> 46337 | E30: =NETWORKDAYS.INTL(C30,D30,"0000100",$C$14) -> 12 | F30: =C30 -> 46324 | G30: =D30 -> 46337 | H30: =E30 -> 12 | I30: Activity QCD18TSECONT2INS1030, 29-Oct to 11-Nov-2026, 12 working days
A31: P11 | B31: Tank 2 - bracing (working days) | C31: =$C$394 -> 46327 | D31: =$D$394 -> 46343 | E31: =NETWORKDAYS.INTL(C31,D31,"0000100",$C$14) -> 15 | F31: =C31 -> 46327 | G31: =D31 -> 46343 | H31: =E31 -> 15 | I31: Activity QCD18TSECONT2INS1060, 01 to 17-Nov-2026, 15 working days
A32: P12 | B32: Tank 2 - roof supports and ladder (working days) | C32: =$C$401 -> 46344 | D32: =$D$401 -> 46349 | E32: =NETWORKDAYS.INTL(C32,D32,"0000100",$C$14) -> 5 | F32: =C32 -> 46344 | G32: =D32 -> 46349 | H32: =E32 -> 5 | I32: Activity QCD18TSECONT2INS1040, 18 to 23-Nov-2026, 5 working days
A33: P13 | B33: Tank 2 - roof panels (working days) | C33: =$C$402 -> 46350 | D33: =$D$402 -> 46356 | E33: =NETWORKDAYS.INTL(C33,D33,"0000100",$C$14) -> 6 | F33: =C33 -> 46350 | G33: =D33 -> 46356 | H33: =E33 -> 6 | I33: Activity QCD18TSECONT2INS1050, 24 to 30-Nov-2026, 6 working days
A34: P14 | B34: Tank 2 - mechanical works: nozzles, level transmitter, pipes and fittings (working days) | C34: =$C$403 -> 46354 | D34: =$D$405 -> 46359 | E34: =NETWORKDAYS.INTL(C34,D34,"0000100",$C$14) -> 6 | F34: =C34 -> 46354 | G34: =D34 -> 46359 | H34: =E34 -> 6 | I34: Activities QCD18TSECONT2MW2030, 2040 and 2020, 28-Nov to 03-Dec-2026
A35: P15 | B35: Milestone - SAJCO readiness for the tie-in connections (external) | C35: =$C$406 -> 46359 | D35: =$D$406 -> 46359 | E35: - | F35: =C35 -> 46359 | G35: =D35 -> 46359 | H35: - | I35: Activity QCD18TSECONIF2050, 03-Dec-2026, zero duration. An interface milestone outside the Contractor's control, taken as submitted on both bases; it, not the tank erection, fixes the earliest tie-in date
A36: P16 | B36: Tie-in connections with the existing pump room (working days) | C36: =$C$407 -> 46361 | D36: =$D$407 -> 46364 | E36: =NETWORKDAYS.INTL(C36,D36,"0000100",$C$14) -> 4 | F36: =C36 -> 46361 | G36: =D36 -> 46364 | H36: =E36 -> 4 | I36: Activity QCD18TSECONTC2040, 05 to 08-Dec-2026, 4 working days, following the readiness milestone
A37: P17 | B37: Testing and commissioning as programmed - both tanks in parallel (working days) | C37: =$C$408 -> 46365 | D37: =$D$409 -> 46372 | E37: =NETWORKDAYS.INTL(C37,D37,"0000100",$C$14) -> 7 | F37: - | G37: - | H37: - | I37: Basis A only: activities QCD18TSECONTCT12050 and QCD18TSECONTCT22030, 09 to 16-Dec-2026, 7 working days each, in parallel, with two simultaneous fills. Not carried: the Engineer's (KEO) email of 30-Aug-2026 states that installation and testing will not be in parallel and that one tank is filled and the water re-used for the second. The sequential, task-based sequence carried is at P18 to P22
A38: P18 | B38: Hydrostatic test - Tank 1, before the tie-in (working days) | C38: =G37 -> - | D38: =G37 -> - | E38: =G37 -> - | F38: =WORKDAY.INTL(D28,1,"0000100",$C$14) -> 46343 | G38: =WORKDAY.INTL(F38,H38-1,"0000100",$C$14) -> 46350 | H38: =$E$408 -> 7 | I38: Carried basis: starts the working day after the Tank 1 mechanical works (submitted date) and takes the 7 working days the Contractor programmed per tank. Elapsed sequence assumed within those 7 days: tankered filling about 5 working days, the 24-hour hold (unattended apart from level readings), inspection of joints and nozzles and records 1 day. The fill rate is an assumption, not a measured throughput: 3,774 m3 in 5 days needs about 750 m3 a day, for example two 30 m3 tankers on about 12 round trips each, which depends on the water source the Employer has yet to confirm; if the source is further away the elapsed time lengthens but the attendance does not. Attendance: the QA/QC inspector (1.3, monthly) and the commissioning engineer for one day at the end of the hold (7.13); the supplier's leak-test supervision is within Item 6. It sits inside the 15 working days of float the programme gives Tank 1 (17 to 24-Nov-2026). Conditional on an Engineer-approved method: internals flushed and nozzles blind-flanged (RFP Scope of Works work packages 4 and 5), the water retained in Tank 1 until Tank 2 is ready, losses at 'Build-Up' line 7.5
A39: P19 | B39: Transfer of the test water from Tank 1 to Tank 2 (working days) | C39: =G37 -> - | D39: =G37 -> - | E39: =G37 -> - | F39: =WORKDAY.INTL(MAX(G38,G34),1,"0000100",$C$14) -> 46361 | G39: =WORKDAY.INTL(F39,H39-1,"0000100",$C$14) -> 46363 | H39: 3 | I39: Starts the working day after both the Tank 1 test has passed (P18) and Tank 2 is ready to receive water (mechanical works complete, P14, interior flushed). Pumped tank to tank through temporary hoses with the outlet valves isolated; the tie-in is not needed for the transfer. 3 working days is an assessed assumption pending the Contractor's method statement: 3,774 m3 at about 130 m3 an hour over 10-hour shifts, a 150 mm self-priming diesel pump against a low head (adjacent tanks at one level, about 4 m static plus hose friction) - 'Build-Up' lines 7.2 to 7.4
A40: P20 | B40: Hydrostatic test - Tank 2, after the transfer (working days) | C40: =G37 -> - | D40: =G37 -> - | E40: =G37 -> - | F40: =WORKDAY.INTL(G39,1,"0000100",$C$14) -> 46364 | G40: =WORKDAY.INTL(F40,H40-1,"0000100",$C$14) -> 46368 | H40: 4 | I40: Elapsed: the Tank 2 test sequence is 7 working days from the start of the transfer, the same as the programme's per-tank figure - 3 days of transfer (P19, attended by the transfer labour at 7.4), then 4 days here: top-up to test level (1), the 24-hour hold (1, unattended apart from level readings), inspection of joints and nozzles and records (2). Attendance as for P18. Assessed assumption
A41: P21 | B41: Component and subsystem checks after the tie-in - instruments, nozzles, valves, ladders; tank-pump-network interfaces (working days) | C41: =G37 -> - | D41: =G37 -> - | E41: =G37 -> - | F41: =WORKDAY.INTL(G36,1,"0000100",$C$14) -> 46365 | G41: =WORKDAY.INTL(F41,H41-1,"0000100",$C$14) -> 46368 | H41: 3 | I41: RFP Scope of Works 5.2, component testing and subsystem validation. Follows the tie-in and may overlap the Tank 2 hydrostatic test, because these checks do not need both tanks in service. 3 working days is an assessed assumption, not a programme figure: the Contractor's programme has no separate activity for this stage (its two 7-working-day 'Testing & Commissioning' activities cover the hydrostatic test and the commissioning of each tank together). Staffing at 'Build-Up' lines 7.13 to 7.18
A42: P21b | B42: Integrated system commissioning - full operational demonstration and witness testing (working days) | C42: =G37 -> - | D42: =G37 -> - | E42: =G37 -> - | F42: =WORKDAY.INTL(MAX(G36,G40,G41),1,"0000100",$C$14) -> 46369 | G42: =WORKDAY.INTL(F42,H42-1,"0000100",$C$14) -> 46371 | H42: 3 | I42: RFP Scope of Works 5.2, integrated system commissioning. Starts the working day after the last of the tie-in (P16), the Tank 2 hydrostatic test (P20) and the component checks (P21): both tanks must have passed and be connected before full operation is demonstrated. 3 working days (pump interface run, network demonstration, witnessed test and records) is an assessed assumption on the same footing as P21
A43: P22 | B43: Completion of testing and commissioning - both tanks | C43: =$D$410 -> 46372 | D43: =C43 -> 46372 | E43: - | F43: =G42 -> 46371 | G43: =F43 -> 46371 | H43: - | I43: A: completion milestones QCD18TSEOMS1040 and 1050, 16-Dec-2026, with parallel testing. B: end of the integrated system commissioning, conditional on the Tank 1 test preceding the tie-in (P18); if it cannot, see sensitivity S2
...

Sheet Superseded Proposal (Ref)
A1: SUPERSEDED PROPOSAL - REFERENCE ONLY
A2: Contractor's earlier proposal for 3 No. GRP tanks of 3,000 m3 each - SAR 9,149,460.00 excluding VAT
A3: Contractor: SAMA Construction | Superseded by the revised proposal SAMACO-RRFP-000001 dated 13-Aug-2026
A4: Reproduced as submitted for reference. The Engineer's RFP-027 dated 28-Jun-2026 changed the scheme to 2 No. tanks of 4,080 m3 on the existing foundations, and the revised proposal replaced this one. It is not assessed.
C5: CONTRACTOR PROPOSAL (SAMA CONSTRUCTION)
A6: Item | B6: Description | C6: Unit | D6: Qty | E6: Rate (SAR) | F6: Amount (SAR) | G6: Remarks
A7: PRELIMINARY WORK
A8: 1 | B8: Site Mobilization & Demobilization Works Site Mobilization and Demobilization of Site temporary Facilities, Welfare, Personnel, Equipment, and Resources | C8: LS | D8: 1 | E8: 816000 | F8: 816000
A9: DESIGN AND ENGINEERING
A10: 2 | B10: Site Mobilization & Demobilization Works Performing the complete design and engineering for GRP water tanks, including tank sizing, structural analysis, panel arrangement, foundation reaction loads, nozzle orientation, accessories layout, shop drawings, technical submittals and method statments in accordance with project specifications and applicable standards. | C10: LS | D10: 1 | E10: 102000 | F10: 102000
A11: SURVEY WORKS
A12: 3 | B12: Topographic survey The topographic survey includes the location, dimensions and characterization of natural and man-made elements within and around the 3rd tank area, for detailed work shall based on topographic specification | C12: LS | D12: 1 | E12: 18000 | F12: 18000
A13: 4 | B13: Geotechnical survey Carrying out the Geotechnical Investigation in accordance with QIC requirements and SBC 303 (2018), including boreholes up to 15 m depth or 3 m into competent rock, or until refusal strata (SPT N >100) is encountered (If required). The investigation shall include the required field and laboratory testing to determine soil characteristics, groundwater conditions, safe bearing capacity (SBC), settlement, and foundation recommendations for the proposed GRP water tank foundation. Testing shall include, but not be limited to, SPT, soil classification, compaction, shear strength, consolidation, chemical analysis, and rock assessment where applicable. The Geotechnical Report shall include foundation recommendations, allowable bearing capacity, settlement analysis, pile capacity assessment (if required), and all relevant geotechnical design parameters in compliance with QIC requirements and SBC 303 (2018). Trial pits shall be carried out where undisturbed sampling is not achievable, with pit depth extending at least to the proposed foundation level. | C13: LS | D13: 1 | E13: 31500 | F13: 31500
A14: EARTHWORKS
A15: 5 | B15: Site clearance with compaction Stripping and grubbing of top soil layer including bushes, grass, and/or contamination, grading and compaction for subsequent work, disposal of soil and vegetation to the designated area, inspections and Compaction tests. | C15: m² | D15: 1050 | E15: 6 | F15: 6300
A16: 6 | B16: Excavation Excavation of normal soil for general excavation, loading and transportation of excavated soil to the designated stockpile area for future re-use or directly to the backfill area within the site, protection of excavated area from debris, water, and other unsuitable material, provision of protective system for excavation slope if applicable | C16: m³ | D16: 1050 | E16: 54 | F16: 56700
